<?xml version="1.0"?>
<robot xmlns:xacro="http://www.ros.org/wiki/xacro">
  <!-- Wheel link macro definition -->
  <xacro:macro name="wheel_link_xacro" params="wheel_name mesh_file ixx ixy ixz iyy iyz izz joint_origin_xyz joint_name axis_xyz inertial_origin">
    <link name="${wheel_name}">
      <inertial>
        <!-- Inertial origin is passed as a parameter -->
        <origin xyz="${inertial_origin}" rpy="0 0 0" />
        <mass value="3564.1" />
        <inertia 
          ixx="${ixx}" ixy="${ixy}" ixz="${ixz}"
          iyy="${iyy}" iyz="${iyz}" izz="${izz}" />
      </inertial>
      
      <visual>
        <origin xyz="0 0 0" rpy="0 0 0" />
        <geometry>
          <mesh filename="package://omnicar_description/meshes/${mesh_file}.STL" />
        </geometry>
        <material name="">
          <color rgba="0.79216 0 0 1" />
        </material>
      </visual>
      
      <collision>
        <origin xyz="0 0 0" rpy="0 0 0" />
        <geometry>
          <mesh filename="package://omnicar_description/meshes/${mesh_file}.STL" />
        </geometry>
      </collision>
    </link>

    Define the wheel joint
    <joint name="${joint_name}" type="continuous">
      <origin xyz="${joint_origin_xyz}" rpy="0 0 0" />
      <parent link="base_link" />
      <child link="${wheel_name}" />
      <axis xyz="${axis_xyz}" />
    </joint>
  </xacro:macro>

  <!-- Define four wheel links using the macro
  <xacro:wheel_link_xacro 
    wheel_name="lfw_link" 
    mesh_file="lfw_link" 
    ixx="1903.6" ixy="0.0042877" ixz="-0.00063501" iyy="3077.9" iyz="-0.92374" izz="1903.7"
    joint_origin_xyz="3.43623010736038 0.7075 1.22983820805844"
    joint_name="lfw_joint" 
    axis_xyz="0 1 0"
    inertial_origin="-5.9137E-05 1.4802 0.013075" />

  <xacro:wheel_link_xacro 
    wheel_name="lbw_link" 
    mesh_file="lbw_link" 
    ixx="1903.6" ixy="-0.014845" ixz="0.0022512" iyy="3077.9" iyz="-0.92363" izz="1903.7"
    joint_origin_xyz="-3.44119528769102 0.7075 1.22983820805844"
    joint_name="lbw_joint" 
    axis_xyz="0 1 0"
    inertial_origin="0.00021166 1.4802 0.013074" />

  <xacro:wheel_link_xacro 
    wheel_name="rfw_link" 
    mesh_file="rfw_link" 
    ixx="1903.6" ixy="-0.0048169" ixz="-0.00073967" iyy="3077.9" iyz="0.92373" izz="1903.7"
    joint_origin_xyz="3.43623010736038 -0.692500000000002 1.22983820805844"
    joint_name="rfw_joint" 
    axis_xyz="0 1 0"
    inertial_origin="-6.9733E-05 -1.4802 0.013075" />

  <xacro:wheel_link_xacro 
    wheel_name="rbw_link" 
    mesh_file="rbw_link" 
    ixx="1903.6" ixy="0.01814" ixz="0.0027324" iyy="3077.9" iyz="0.92357" izz="1903.7"
    joint_origin_xyz="-3.44119528769102 -0.692499999999999 1.22983820805844"
    joint_name="rbw_joint" 
    axis_xyz="0 1 0"
    inertial_origin="0.00025519 -1.4802 0.013073" /> -->
</robot>
